2020-01-30 21:25:19,312 ERROR: Exception on / [GET] [in /home/whisllayjr/Documentos/mymicroblog/venv/lib64/python3.7/site-packages/flask/app.py:1891]
Traceback (most recent call last):
  File "/home/whisllayjr/Documentos/mymicroblog/venv/lib64/python3.7/site-packages/flask/app.py", line 2446, in wsgi_app
    response = self.full_dispatch_request()
  File "/home/whisllayjr/Documentos/mymicroblog/venv/lib64/python3.7/site-packages/flask/app.py", line 1951, in full_dispatch_request
    rv = self.handle_user_exception(e)
  File "/home/whisllayjr/Documentos/mymicroblog/venv/lib64/python3.7/site-packages/flask/app.py", line 1820, in handle_user_exception
    reraise(exc_type, exc_value, tb)
  File "/home/whisllayjr/Documentos/mymicroblog/venv/lib64/python3.7/site-packages/flask/_compat.py", line 39, in reraise
    raise value
  File "/home/whisllayjr/Documentos/mymicroblog/venv/lib64/python3.7/site-packages/flask/app.py", line 1949, in full_dispatch_request
    rv = self.dispatch_request()
  File "/home/whisllayjr/Documentos/mymicroblog/venv/lib64/python3.7/site-packages/flask/app.py", line 1935, in dispatch_request
    return self.view_functions[rule.endpoint](**req.view_args)
  File "/home/whisllayjr/Documentos/mymicroblog/venv/lib64/python3.7/site-packages/flask_login/utils.py", line 261, in decorated_view
    return func(*args, **kwargs)
  File "/home/whisllayjr/Documentos/mymicroblog/app/routes.py", line 36, in index
    return render_template('index.html', title=_('Home'), form=form,
  File "/home/whisllayjr/Documentos/mymicroblog/venv/lib64/python3.7/site-packages/flask_babel/__init__.py", line 552, in gettext
    t = get_translations()
  File "/home/whisllayjr/Documentos/mymicroblog/venv/lib64/python3.7/site-packages/flask_babel/__init__.py", line 227, in get_translations
    [get_locale()],
  File "/home/whisllayjr/Documentos/mymicroblog/venv/lib64/python3.7/site-packages/flask_babel/__init__.py", line 257, in get_locale
    rv = babel.locale_selector_func()
  File "/home/whisllayjr/Documentos/mymicroblog/app/__init__.py", line 55, in get_locale
    return pt
NameError: name 'pt' is not defined
2020-01-30 21:25:35,078 INFO: Microblog startup [in /home/whisllayjr/Documentos/mymicroblog/app/__init__.py:50]
2020-01-30 21:26:21,474 INFO: Microblog startup [in /home/whisllayjr/Documentos/mymicroblog/app/__init__.py:50]
2020-01-30 21:49:38,924 INFO: Microblog startup [in /home/whisllayjr/Documentos/mymicroblog/app/__init__.py:50]
2020-01-30 21:50:23,330 INFO: Microblog startup [in /home/whisllayjr/Documentos/mymicroblog/app/__init__.py:50]
